Workbook

Sheet Summary
A1: Shiftwell – Step 1 analysis (all cells are live formulas)
A3: 1. ARR at risk and renewal timing
A4: Total ARR (₹ lakh) | B4: =Accounts!D10 -> 408
A5: ARR of 'At risk' accounts (₹ lakh) | B5: =SUMIFS(Accounts!D2:D9,Accounts!J2:J9,"At risk") -> 184
A6: …as % of total ARR | B6: =B5/B4 -> 0.45098039
A7: ARR renewing by 31 Jan 2027 (₹ lakh) | B7: =SUMIFS(Accounts!D2:D9,Accounts!E2:E9,"<="&DATE(2027,1,31)) -> 184 | C7: Next ~4 months, before this quarter's build can fully land
A8: …as % of total ARR | B8: =B7/B4 -> 0.45098039
A9: ARR renewing by 31 Jan 2027 AND At risk (₹ lakh) | B9: =SUMIFS(Accounts!D2:D9,Accounts!E2:E9,"<="&DATE(2027,1,31),Accounts!J2:J9,"At risk") -> 184
A10: UrbanMart ARR (₹ lakh) / % of total | B10: =Accounts!D2 -> 110 | C10: =Accounts!D2/B4 -> 0.26960784
A11: UrbanMart months to renewal (from 16 Oct 2026) | B11: =DATEDIF(DATE(2026,10,16),Accounts!E2,"m") -> 9 | C11: Assumed 'today' = 16 Oct 2026
A13: 2. Swap approval rate vs health
A14: Avg 24h approval – At risk accounts | B14: =AVERAGEIFS(Accounts!H2:H9,Accounts!J2:J9,"At risk") -> 0.4325
A15: Avg 24h approval – Healthy accounts | B15: =AVERAGEIFS(Accounts!H2:H9,Accounts!J2:J9,"Healthy") -> 0.70333333
A16: Avg 24h approval – Watch | B16: =AVERAGEIFS(Accounts!H2:H9,Accounts!J2:J9,"Watch") -> 0.41
A17: Avg 24h approval – Lost accounts (last 3 mo) | B17: =Lost!F8 -> 0.365
A18: Accounts with approval <50% | B18: =SUM(Accounts!O2:O9) -> 4
A19: …of which also 'At risk' or 'Watch' (count) | B19: =COUNTIFS(Accounts!O2:O9,1,Accounts!J2:J9,"<>Healthy") -> 4 | C19: Should equal row 18 if the pattern is clean
A20: ARR in accounts with approval <50% (₹ lakh) | B20: =SUMIFS(Accounts!D2:D9,Accounts!O2:O9,1) -> 160
A21: …as % of total ARR | B21: =B20/B4 -> 0.39215686
A23: 3. Manager time on scheduling
A24: Avg mgr hrs/wk – At risk | B24: =AVERAGEIFS(Accounts!I2:I9,Accounts!J2:J9,"At risk") -> 5.75
A25: Avg mgr hrs/wk – Healthy | B25: =AVERAGEIFS(Accounts!I2:I9,Accounts!J2:J9,"Healthy") -> 3
A26: Correlation: approval rate vs mgr hrs/wk | B26: =CORREL(Accounts!H2:H9,Accounts!I2:I9) -> -0.95125497 | C26: Strong negative = slow approvals go with heavy manager load. n=8, so directional only
A27: Correlation: approval rate vs at-risk flag | B27: =CORREL(Accounts!H2:H9,Accounts!N2:N9) -> -0.54371672 | C27: Negative = lower approval, more likely at risk. n=8
A29: 4. Swap load
A30: Swaps / location / month – FreshBowl | B30: =Accounts!K3 -> 24.166667
A31: Swaps / location / month – UrbanMart | B31: =Accounts!K2 -> 15.5
A32: Swaps / location / month – CarePoint | B32: =Accounts!K4 -> 7.75
A33: Swaps / location / month – Brew & Co | B33: =Accounts!K9 -> 23.428571
A34: Swaps / location / month – all accounts | B34: =Accounts!G10/Accounts!C10 -> 16.387097
A35: FreshBowl swaps per manager per night (approx) | B35: =Accounts!G3/Accounts!C3/30 -> 0.80555556 | C35: Interview says 25–30/night; compare. Assumes 1 manager per location, 30 days
A37: 5. Cost of WhatsApp (assumption-driven)
A38: Cost per WhatsApp message (₹) | B38: 0.35 | C38: From engineering notes
A39: Messages per swap (assumed) | B39: 4 | C39: ASSUMPTION: request, notify colleague, approval ask, outcome. Change me
A40: FreshBowl WhatsApp cost / year (₹ lakh) | B40: =Accounts!G3*B39*B38*12/100000 -> 0.4872
A41: …as % of FreshBowl ARR | B41: =B40/(Accounts!D3) -> 0.0058
A43: 6. Sprint budget (6 available)
A44: Sprints available | B44: 6
A45: WhatsApp | B45: 3
A46: Overtime approval (custom) | B46: 2
...

Sheet Accounts
A1: Account | B1: Segment | C1: Locations | D1: ARR (₹ lakh) | E1: Renewal due | F1: Staff on app | G1: Swap requests / month | H1: Swaps approved <24h | I1: Mgr hrs / week on scheduling | J1: Health (CS) | K1: Swaps per location / month | L1: Swaps per staff / month | M1: ARR per location (₹ lakh) | N1: At risk? (1/0) | O1: Approval <50%? (1/0)
A2: UrbanMart | B2: Retail | C2: 200 | D2: 110 | E2: 46600 | F2: 5200 | G2: 3100 | H2: 0.64 | I2: 3.5 | J2: Healthy | K2: =G2/C2 -> 15.5 | L2: =G2/F2 -> 0.59615385 | M2: =D2/C2 -> 0.55 | N2: =IF(J2="At risk",1,0) -> 0 | O2: =IF(H2<0.5,1,0) -> 0
A3: FreshBowl | B3: Restaurants | C3: 120 | D3: 84 | E3: 46388 | F3: 3600 | G3: 2900 | H3: 0.38 | I3: 6.5 | J3: At risk | K3: =G3/C3 -> 24.166667 | L3: =G3/F3 -> 0.80555556 | M3: =D3/C3 -> 0.7 | N3: =IF(J3="At risk",1,0) -> 1 | O3: =IF(H3<0.5,1,0) -> 1
A4: CarePoint Clinics | B4: Clinics | C4: 40 | D4: 60 | E4: 46357 | F4: 900 | G4: 310 | H4: 0.71 | I4: 4 | J4: At risk | K4: =G4/C4 -> 7.75 | L4: =G4/F4 -> 0.34444444 | M4: =D4/C4 -> 1.5 | N4: =IF(J4="At risk",1,0) -> 1 | O4: =IF(H4<0.5,1,0) -> 0
A5: QuickKart | B5: Retail | C5: 90 | D5: 48 | E5: 46539 | F5: 2100 | G5: 1000 | H5: 0.67 | I5: 3 | J5: Healthy | K5: =G5/C5 -> 11.111111 | L5: =G5/F5 -> 0.47619048 | M5: =D5/C5 -> 0.53333333 | N5: =IF(J5="At risk",1,0) -> 0 | O5: =IF(H5<0.5,1,0) -> 0
A6: Spice Route | B6: Restaurants | C6: 60 | D6: 36 | E6: 46447 | F6: 1500 | G6: 1400 | H6: 0.41 | I6: 6 | J6: Watch | K6: =G6/C6 -> 23.333333 | L6: =G6/F6 -> 0.93333333 | M6: =D6/C6 -> 0.6 | N6: =IF(J6="At risk",1,0) -> 0 | O6: =IF(H6<0.5,1,0) -> 1
A7: MedAxis Labs | B7: Diagnostics | C7: 25 | D7: 30 | E7: 46419 | F7: 450 | G7: 90 | H7: 0.8 | I7: 2.5 | J7: Healthy | K7: =G7/C7 -> 3.6 | L7: =G7/F7 -> 0.2 | M7: =D7/C7 -> 1.2 | N7: =IF(J7="At risk",1,0) -> 0 | O7: =IF(H7<0.5,1,0) -> 0
A8: FitZone | B8: Gyms | C8: 50 | D8: 22 | E8: 46296 | F8: 600 | G8: 540 | H8: 0.35 | I8: 5.5 | J8: At risk | K8: =G8/C8 -> 10.8 | L8: =G8/F8 -> 0.9 | M8: =D8/C8 -> 0.44 | N8: =IF(J8="At risk",1,0) -> 1 | O8: =IF(H8<0.5,1,0) -> 1
A9: Brew & Co | B9: Cafes | C9: 35 | D9: 18 | E9: 46327 | F9: 700 | G9: 820 | H9: 0.29 | I9: 7 | J9: At risk | K9: =G9/C9 -> 23.428571 | L9: =G9/F9 -> 1.1714286 | M9: =D9/C9 -> 0.51428571 | N9: =IF(J9="At risk",1,0) -> 1 | O9: =IF(H9<0.5,1,0) -> 1
A10: Total | C10: =SUM(C2:C9) -> 620 | D10: =SUM(D2:D9) -> 408 | F10: =SUM(F2:F9) -> 15050 | G10: =SUM(G2:G9) -> 10160
A12: Legend: blue text = data pasted from the case pack (edit here). Shaded columns K–O = formulas, do not overwrite.
A13: Check: ARR total should equal 408 lakh (₹4.08 Cr) per the brief. | E13: =IF(D10=408,"OK","MISMATCH") -> OK
A14: Assumption: renewal dates set to the 1st of the stated month (case gives month only).

Sheet Lost
A1: Account | B1: Segment | C1: Locations | D1: ARR lost (₹ lakh) | E1: Reason recorded by sales | F1: Swaps approved <24h (last 3 mo)
A2: StyleHub | B2: Retail | C2: 70 | D2: 30 | E2: Budget cuts | F2: 0.6
A3: TandooriTown | B3: Restaurants | C3: 45 | D3: 25 | E3: Price | F3: 0.22
A4: GreenLeaf Salads | B4: Restaurants | C4: 30 | D4: 16 | E4: Moved to RotaPro (has WhatsApp) | F4: 0.31
A5: PawsCare Vets | B5: Clinics | C5: 15 | D5: 9 | E5: Went back to spreadsheets | F5: 0.33
A7: Total ARR lost | D7: =SUM(D2:D5) -> 80
A8: Avg approval rate, lost accounts | F8: =AVERAGE(F2:F5) -> 0.365
A9: Lost accounts with approval <50% | F9: =COUNTIF(F2:F5,"<0.5")&" of "&COUNT(F2:F5) -> 3 of 4
A10: ARR lost where approval <50% | D10: =SUMIF(F2:F5,"<0.5",D2:D5) -> 50
A11: …as % of all ARR lost | D11: =D10/D7 -> 0.625
